Workbook
Name QID_List: Student_Master!$B$2:$B$232
Name Student_Name_List: Student_Master!$C$2:$C$232

Sheet README
A1: QSTSS Students Growth Dashboard
A3: Purpose | B3: Show student growth pre-QSTSS, during QSTSS, and at graduation / university destination.
A4: Internal longitudinal source | B4: Panel_Data_QSTSS Marks analysis.xlsx (3 cohorts, 4 years each).
A5: Pre-QSTSS baseline source | B5: QID-matched admissions baseline source. Attached file includes Classes of 2024 and 2025; Class of 2023 remains formula-ready but requires a 2023 admissions source file to populate.
A6: Graduation / destination source | B6: University admission files for Classes of 2023, 2024, and 2025.
A7: External readiness source | B7: SAT from university admission files; school-level SAT / IELTS / AP trend from attached reports.
A8: How to use | B8: Start with Dashboard_Executive. Use Student_Profile to select a QID and view baseline -> QSTSS trajectory -> graduation outcomes.
A9: Important note | B9: Teacher-level and student-level engagement fields are included as structured sheets, but only the indicators supported by uploaded evidence are populated.
A11: Manual baseline update workflow | B11: Admissions_2024_2025 is rebuilt in Student_Master QID order. Baseline_Entry, Student_Master, Student_Growth, Cognitive_Profile, Student_Profile, and dashboard lookups now use XLOOKUP with error handling.
A12: Admissions_2024_2025 editable columns | B12: D:W (prior school through source).
A13: Calculated fields | B13: Baseline_Entry K, M, N, O, P, Q are formula-driven from admission inputs and CAT4 subscales.
A14: Baseline_Composite logic | B14: AVERAGE(APTIS_%, Math_%, CAT4_%).
A15: Student_Master baseline | B15: Column I now looks up Baseline_Composite from Baseline_Entry.
... A20: University and Major source refreshed from attached cohort workbook on separate cohort sheets. | B20: Student_Profile, Dashboard_Executive, and all chart sheets were rebuilt and standardized for publication-ready presentation.
A21: Student_Profile University, Major, Sponsor, Final Secondary %, and SAT Total now resolve directly from University_Exit by QID.
A22: Enhancements added in this version
A23: 1. Student_Profile now supports search using either QID or student name via paired input fields and a resolved QID helper.
A24: 2. CAT4_Current_Master refreshed from CAT4 all grade levels.xlsx to populate current cognitive values, including Class of 2022 where available.
A25: 3. Automatic cognitive classification and evidence-style interpretation have been added in Student_Profile and Cognitive_Profile.
A26: 4. New sheet Cognia_Evidence_Page provides a cohort-level evidence snapshot with KPIs, summaries, and charts.

Sheet Student_Master
A1: Cohort | B1: QID | C1: Student_Name | D1: Entry_Year | E1: Exit_Year | F1: Entry_Overall | G1: Exit_Overall | H1: Gain_Overall | I1: Baseline_Composite | J1: Baseline_Available_Flag | K1: Starter_Group | L1: Entry_Band | M1: Exit_Band | N1: Band_Movement | O1: University | P1: Major | Q1: STEM_Major_Flag | R1: Direct_Admission_Flag | S1: Final_Secondary_% | T1: SAT_Total | U1: Sponsor
A2: Class of 2022 | B2: 30463404774 | C2: حسن اسماعيل على العمادى | D2: 2018/2019 | E2: 2021/2022 | F2: 89.568 | G2: 96.024 | H2: 6.456 | I2: =IFERROR(INDEX(Baseline_Entry!$P:$P,MATCH($B2,Baseline_Entry!$B:$B,0)),"") -> 83 | J2: =IF(I2="","No","Yes") -> Yes | K2: =IF(IF(I2="",F2,I2)<70,"Low starter",IF(IF(I2="",F2,I2)<85,"Middle starter","High starter")) -> Middle starter | L2: 80-89 | M2: 90+ | N2: 1 | O2: =IFERROR(INDEX(University_Exit!$D:$D,MATCH($B2,University_Exit!$B:$B,0)),"") -> University of Liverpool | P2: =IFERROR(INDEX(University_Exit!$F:$F,MATCH($B2,University_Exit!$B:$B,0)),"") -> Electrical Engineering | Q2: =IFERROR(INDEX(University_Exit!$L:$L,MATCH($B2,University_Exit!$B:$B,0)),"") -> Yes | R2: =IF(O2="","No","Yes") -> Yes | S2: =IFERROR(INDEX(University_Exit!$H:$H,MATCH($B2,University_Exit!$B:$B,0)),"") -> 96.3 | T2: =IFERROR(INDEX(University_Exit!$K:$K,MATCH($B2,University_Exit!$B:$B,0)),"") -> 930 | U2: =IFERROR(INDEX(University_Exit!$G:$G,MATCH($B2,University_Exit!$B:$B,0)),"") -> Qatar Energy
A3: Class of 2022 | B3: 30463400105 | C3: سيف احمد محمد السليطى | D3: 2018/2019 | E3: 2021/2022 | F3: 92.748 | G3: 97.676 | H3: 4.928 | I3: =IFERROR(INDEX(Baseline_Entry!$P:$P,MATCH($B3,Baseline_Entry!$B:$B,0)),"") -> 94.4 | J3: =IF(I3="","No","Yes") -> Yes | K3: =IF(IF(I3="",F3,I3)<70,"Low starter",IF(IF(I3="",F3,I3)<85,"Middle starter","High starter")) -> High starter | L3: 90+ | M3: 90+ | N3: 0 | O3: =IFERROR(INDEX(University_Exit!$D:$D,MATCH($B3,University_Exit!$B:$B,0)),"") -> Qatar University | P3: =IFERROR(INDEX(University_Exit!$F:$F,MATCH($B3,University_Exit!$B:$B,0)),"") -> Computer Science | Q3: =IFERROR(INDEX(University_Exit!$L:$L,MATCH($B3,University_Exit!$B:$B,0)),"") -> Yes | R3: =IF(O3="","No","Yes") -> Yes | S3: =IFERROR(INDEX(University_Exit!$H:$H,MATCH($B3,University_Exit!$B:$B,0)),"") -> 98.2 | T3: =IFERROR(INDEX(University_Exit!$K:$K,MATCH($B3,University_Exit!$B:$B,0)),"") -> 1150 | U3: =IFERROR(INDEX(University_Exit!$G:$G,MATCH($B3,University_Exit!$B:$B,0)),"") -> خاص/ مجاني
A4: Class of 2022 | B4: 30463401069 | C4: سيف على ابراهيم المهندى | D4: 2018/2019 | E4: 2021/2022 | F4: 91.216 | G4: 99.44 | H4: 8.224 | I4: =IFERROR(INDEX(Baseline_Entry!$P:$P,MATCH($B4,Baseline_Entry!$B:$B,0)),"") -> 82 | J4: =IF(I4="","No","Yes") -> Yes | K4: =IF(IF(I4="",F4,I4)<70,"Low starter",IF(IF(I4="",F4,I4)<85,"Middle starter","High starter")) -> Middle starter | L4: 90+ | M4: 90+ | N4: 0 | O4: =IFERROR(INDEX(University_Exit!$D:$D,MATCH($B4,University_Exit!$B:$B,0)),"") -> University of Liverpool | P4: =IFERROR(INDEX(University_Exit!$F:$F,MATCH($B4,University_Exit!$B:$B,0)),"") -> Electric and Electronic Engineering | Q4: =IFERROR(INDEX(University_Exit!$L:$L,MATCH($B4,University_Exit!$B:$B,0)),"") -> Yes | R4: =IF(O4="","No","Yes") -> Yes | S4: =IFERROR(INDEX(University_Exit!$H:$H,MATCH($B4,University_Exit!$B:$B,0)),"") -> 98.8 | T4: =IFERROR(INDEX(University_Exit!$K:$K,MATCH($B4,University_Exit!$B:$B,0)),"") -> 1050 | U4: =IFERROR(INDEX(University_Exit!$G:$G,MATCH($B4,University_Exit!$B:$B,0)),"") -> Qatar Energy
A5: Class of 2022 | B5: 30463402074 | C5: عبدالرحمن عبدالعزيز اسماعيل الهاشمى | D5: 2018/2019 | E5: 2021/2022 | F5: 89.112 | G5: 94.852 | H5: 5.74 | I5: =IFERROR(INDEX(Baseline_Entry!$P:$P,MATCH($B5,Baseline_Entry!$B:$B,0)),"") -> 79.2 | J5: =IF(I5="","No","Yes") -> Yes | K5: =IF(IF(I5="",F5,I5)<70,"Low starter",IF(IF(I5="",F5,I5)<85,"Middle starter","High starter")) -> Middle starter | L5: 80-89 | M5: 90+ | N5: 1 | O5: =IFERROR(INDEX(University_Exit!$D:$D,MATCH($B5,University_Exit!$B:$B,0)),"") -> Texas A&M University Qatar | P5: =IFERROR(INDEX(University_Exit!$F:$F,MATCH($B5,University_Exit!$B:$B,0)),"") -> Mechanical Engineering | Q5: =IFERROR(INDEX(University_Exit!$L:$L,MATCH($B5,University_Exit!$B:$B,0)),"") -> Yes | R5: =IF(O5="","No","Yes") -> Yes | S5: =IFERROR(INDEX(University_Exit!$H:$H,MATCH($B5,University_Exit!$B:$B,0)),"") -> 94.4 | T5: =IFERROR(INDEX(University_Exit!$K:$K,MATCH($B5,University_Exit!$B:$B,0)),"") -> 1110 | U5: =IFERROR(INDEX(University_Exit!$G:$G,MATCH($B5,University_Exit!$B:$B,0)),"") -> Qatar Energy
A6: Class of 2022 | B6: 30463400747 | C6: عبدالرحمن عبدالله عزالدين المطوع | D6: 2018/2019 | E6: 2021/2022 | F6: 89.588 | G6: 96.376 | H6: 6.788 | I6: =IFERROR(INDEX(Baseline_Entry!$P:$P,MATCH($B6,Baseline_Entry!$B:$B,0)),"") -> 86.6 | J6: =IF(I6="","No","Yes") -> Yes | K6: =IF(IF(I6="",F6,I6)<70,"Low starter",IF(IF(I6="",F6,I6)<85,"Middle starter","High starter")) -> High starter | L6: 80-89 | M6: 90+ | N6: 1 | O6: =IFERROR(INDEX(University_Exit!$D:$D,MATCH($B6,University_Exit!$B:$B,0)),"") -> University of Liverpool | P6: =IFERROR(INDEX(University_Exit!$F:$F,MATCH($B6,University_Exit!$B:$B,0)),"") -> Mechanical Engineering | Q6: =IFERROR(INDEX(University_Exit!$L:$L,MATCH($B6,University_Exit!$B:$B,0)),"") -> Yes | R6: =IF(O6="","No","Yes") -> Yes | S6: =IFERROR(INDEX(University_Exit!$H:$H,MATCH($B6,University_Exit!$B:$B,0)),"") -> 96.9 | T6: =IFERROR(INDEX(University_Exit!$K:$K,MATCH($B6,University_Exit!$B:$B,0)),"") -> 1050 | U6: =IFERROR(INDEX(University_Exit!$G:$G,MATCH($B6,University_Exit!$B:$B,0)),"") -> Ministry of Education
A7: Class of 2022 | B7: 30463402384 | C7: عبدالرحمن محمد سعد السليطى | D7: 2018/2019 | E7: 2021/2022 | F7: 92.432 | G7: 95.252 | H7: 2.82 | I7: =IFERROR(INDEX(Baseline_Entry!$P:$P,MATCH($B7,Baseline_Entry!$B:$B,0)),"") -> 74.6 | J7: =IF(I7="","No","Yes") -> Yes | K7: =IF(IF(I7="",F7,I7)<70,"Low starter",IF(IF(I7="",F7,I7)<85,"Middle starter","High starter")) -> Middle starter | L7: 90+ | M7: 90+ | N7: 0 | O7: =IFERROR(INDEX(University_Exit!$D:$D,MATCH($B7,University_Exit!$B:$B,0)),"") -> Texas A&M University Qatar | P7: =IFERROR(INDEX(University_Exit!$F:$F,MATCH($B7,University_Exit!$B:$B,0)),"") -> Electric and Electronic Engineering | Q7: =IFERROR(INDEX(University_Exit!$L:$L,MATCH($B7,University_Exit!$B:$B,0)),"") -> Yes | R7: =IF(O7="","No","Yes") -> Yes | S7: =IFERROR(INDEX(University_Exit!$H:$H,MATCH($B7,University_Exit!$B:$B,0)),"") -> 94.9 | T7: =IFERROR(INDEX(University_Exit!$K:$K,MATCH($B7,University_Exit!$B:$B,0)),"") -> 1100 | U7: =IFERROR(INDEX(University_Exit!$G:$G,MATCH($B7,University_Exit!$B:$B,0)),"") -> Qatar Energy
A8: Class of 2022 | B8: 30363404443 | C8: عبدالعزيز صلاح على الانشائى | D8: 2018/2019 | E8: 2021/2022 | F8: 91.532 | G8: 96.452 | H8: 4.92 | I8: =IFERROR(INDEX(Baseline_Entry!$P:$P,MATCH($B8,Baseline_Entry!$B:$B,0)),"") -> 76.2 | J8: =IF(I8="","No","Yes") -> Yes | K8: =IF(IF(I8="",F8,I8)<70,"Low starter",IF(IF(I8="",F8,I8)<85,"Middle starter","High starter")) -> Middle starter | L8: 90+ | M8: 90+ | N8: 0 | O8: =IFERROR(INDEX(University_Exit!$D:$D,MATCH($B8,University_Exit!$B:$B,0)),"") -> Texas A&M University Qatar | P8: =IFERROR(INDEX(University_Exit!$F:$F,MATCH($B8,University_Exit!$B:$B,0)),"") -> Chemical engineering | Q8: =IFERROR(INDEX(University_Exit!$L:$L,MATCH($B8,University_Exit!$B:$B,0)),"") -> Yes | R8: =IF(O8="","No","Yes") -> Yes | S8: =IFERROR(INDEX(University_Exit!$H:$H,MATCH($B8,University_Exit!$B:$B,0)),"") -> 97.9 | T8: =IFERROR(INDEX(University_Exit!$K:$K,MATCH($B8,University_Exit!$B:$B,0)),"") -> 970 | U8: =IFERROR(INDEX(University_Exit!$G:$G,MATCH($B8,University_Exit!$B:$B,0)),"") -> Qatar Energy
A9: Class of 2022 | B9: 30463404428 | C9: عبدالعزيز على يوسف التميمى | D9: 2018/2019 | E9: 2021/2022 | F9: 86.488 | G9: 94.8 | H9: 8.312 | I9: =IFERROR(INDEX(Baseline_Entry!$P:$P,MATCH($B9,Baseline_Entry!$B:$B,0)),"") -> 84.8 | J9: =IF(I9="","No","Yes") -> Yes | K9: =IF(IF(I9="",F9,I9)<70,"Low starter",IF(IF(I9="",F9,I9)<85,"Middle starter","High starter")) -> Middle starter | L9: 80-89 | M9: 90+ | N9: 1 | O9: =IFERROR(INDEX(University_Exit!$D:$D,MATCH($B9,University_Exit!$B:$B,0)),"") -> University of Liverpool | P9: =IFERROR(INDEX(University_Exit!$F:$F,MATCH($B9,University_Exit!$B:$B,0)),"") -> Mechanical Engineering | Q9: =IFERROR(INDEX(University_Exit!$L:$L,MATCH($B9,University_Exit!$B:$B,0)),"") -> Yes | R9: =IF(O9="","No","Yes") -> Yes | S9: =IFERROR(INDEX(University_Exit!$H:$H,MATCH($B9,University_Exit!$B:$B,0)),"") -> 95.3 | T9: =IFERROR(INDEX(University_Exit!$K:$K,MATCH($B9,University_Exit!$B:$B,0)),"") -> 1090 | U9: =IFERROR(INDEX(University_Exit!$G:$G,MATCH($B9,University_Exit!$B:$B,0)),"") -> Shell
A10: Class of 2022 | B10: 30463400925 | C10: عبدالله خالد احمد النصر | D10: 2018/2019 | E10: 2021/2022 | F10: 95.884 | G10: 96.276 | H10: 0.392 | I10: =IFERROR(INDEX(Baseline_Entry!$P:$P,MATCH($B10,Baseline_Entry!$B:$B,0)),"") -> 89 | J10: =IF(I10="","No","Yes") -> Yes | K10: =IF(IF(I10="",F10,I10)<70,"Low starter",IF(IF(I10="",F10,I10)<85,"Middle starter","High starter")) -> High starter | L10: 90+ | M10: 90+ | N10: 0 | O10: =IFERROR(INDEX(University_Exit!$D:$D,MATCH($B10,University_Exit!$B:$B,0)),"") -> Swansea University | P10: =IFERROR(INDEX(University_Exit!$F:$F,MATCH($B10,University_Exit!$B:$B,0)),"") -> Electrical Engineering | Q10: =IFERROR(INDEX(University_Exit!$L:$L,MATCH($B10,University_Exit!$B:$B,0)),"") -> Yes | R10: =IF(O10="","No","Yes") -> Yes | S10: =IFERROR(INDEX(University_Exit!$H:$H,MATCH($B10,University_Exit!$B:$B,0)),"") -> 96.7 | T10: =IFERROR(INDEX(University_Exit!$K:$K,MATCH($B10,University_Exit!$B:$B,0)),"") -> 1050 | U10: =IFERROR(INDEX(University_Exit!$G:$G,MATCH($B10,University_Exit!$B:$B,0)),"") -> Qatar Energy
A11: Class of 2022 | B11: 30463404499 | C11: عبدالله على راشد النجدى | D11: 2018/2019 | E11: 2021/2022 | F11: 87.964 | G11: 92.8 | H11: 4.836 | I11: =IFERROR(INDEX(Baseline_Entry!$P:$P,MATCH($B11,Baseline_Entry!$B:$B,0)),"") -> 54 | J11: =IF(I11="","No","Yes") -> Yes | K11: =IF(IF(I11="",F11,I11)<70,"Low starter",IF(IF(I11="",F11,I11)<85,"Middle starter","High starter")) -> Low starter | L11: 80-89 | M11: 90+ | N11: 1 | O11: =IFERROR(INDEX(University_Exit!$D:$D,MATCH($B11,University_Exit!$B:$B,0)),"") -> Qatar University | P11: =IFERROR(INDEX(University_Exit!$F:$F,MATCH($B11,University_Exit!$B:$B,0)),"") -> Mechanical Engineering | Q11: =IFERROR(INDEX(University_Exit!$L:$L,MATCH($B11,University_Exit!$B:$B,0)),"") -> Yes | R11: =IF(O11="","No","Yes") -> Yes | S11: =IFERROR(INDEX(University_Exit!$H:$H,MATCH($B11,University_Exit!$B:$B,0)),"") -> 92.8 | T11: =IFERROR(INDEX(University_Exit!$K:$K,MATCH($B11,University_Exit!$B:$B,0)),"") -> 1030 | U11: =IFERROR(INDEX(University_Exit!$G:$G,MATCH($B11,University_Exit!$B:$B,0)),"") -> Ministry of Education
A12: Class of 2022 | B12: 30463404313 | C12: غانم عبدالله سالم المرى | D12: 2018/2019 | E12: 2021/2022 | F12: 86.468 | G12: 91.676 | H12: 5.208 | I12: =IFERROR(INDEX(Baseline_Entry!$P:$P,MATCH($B12,Baseline_Entry!$B:$B,0)),"") -> 76 | J12: =IF(I12="","No","Yes") -> Yes | K12: =IF(IF(I12="",F12,I12)<70,"Low starter",IF(IF(I12="",F12,I12)<85,"Middle starter","High starter")) -> Middle starter | L12: 80-89 | M12: 90+ | N12: 1 | O12: =IFERROR(INDEX(University_Exit!$D:$D,MATCH($B12,University_Exit!$B:$B,0)),"") -> Texas A&M University Qatar | P12: =IFERROR(INDEX(University_Exit!$F:$F,MATCH($B12,University_Exit!$B:$B,0)),"") -> Petroleum Engineering | Q12: =IFERROR(INDEX(University_Exit!$L:$L,MATCH($B12,University_Exit!$B:$B,0)),"") -> Yes | R12: =IF(O12="","No","Yes") -> Yes | S12: =IFERROR(INDEX(University_Exit!$H:$H,MATCH($B12,University_Exit!$B:$B,0)),"") -> 91.1 | T12: =IFERROR(INDEX(University_Exit!$K:$K,MATCH($B12,University_Exit!$B:$B,0)),"") -> 1060 | U12: =IFERROR(INDEX(University_Exit!$G:$G,MATCH($B12,University_Exit!$B:$B,0)),"") -> Qatar Energy
A13: Class of 2022 | B13: 30463401470 | C13: ماجد عبدالله ماجد السويدى | D13: 2018/2019 | E13: 2021/2022 | F13: 86.276 | G13: 95.124 | H13: 8.848 | I13: =IFERROR(INDEX(Baseline_Entry!$P:$P,MATCH($B13,Baseline_Entry!$B:$B,0)),"") -> 77.8 | J13: =IF(I13="","No","Yes") -> Yes | K13: =IF(IF(I13="",F13,I13)<70,"Low starter",IF(IF(I13="",F13,I13)<85,"Middle starter","High starter")) -> Middle starter | L13: 80-89 | M13: 90+ | N13: 1 | O13: =IFERROR(INDEX(University_Exit!$D:$D,MATCH($B13,University_Exit!$B:$B,0)),"") -> Texas A&M University Qatar | P13: =IFERROR(INDEX(University_Exit!$F:$F,MATCH($B13,University_Exit!$B:$B,0)),"") -> Mechanical engineering | Q13: =IFERROR(INDEX(University_Exit!$L:$L,MATCH($B13,University_Exit!$B:$B,0)),"") -> Yes | R13: =IF(O13="","No","Yes") -> Yes | S13: =IFERROR(INDEX(University_Exit!$H:$H,MATCH($B13,University_Exit!$B:$B,0)),"") -> 95.8 | T13: =IFERROR(INDEX(University_Exit!$K:$K,MATCH($B13,University_Exit!$B:$B,0)),"") -> 1070 | U13: =IFERROR(INDEX(University_Exit!$G:$G,MATCH($B13,University_Exit!$B:$B,0)),"") -> Qatar Energy
... A232: Class of 2025 | B232: 30763400655 | C232: هزاع عطاالله محمد أبوشريدة | D232: 2021/2022 | E232: 2024/2025 | F232: 82.556 | G232: 92.976 | H232: 10.42 | I232: =IFERROR(INDEX(Baseline_Entry!$P:$P,MATCH($B232,Baseline_Entry!$B:$B,0)),"") -> 59.543662 | J232: =IF(I232="","No","Yes") -> Yes | K232: =IF(IF(I232="",F232,I232)<70,"Low starter",IF(IF(I232="",F232,I232)<85,"Middle starter","High starter")) -> Low starter | L232: 80-89 | M232: 90+ | N232: 1 | O232: =IFERROR(INDEX(University_Exit!$D:$D,MATCH($B232,University_Exit!$B:$B,0)),"") -> Royal College of Surgeons in Ireland | P232: =IFERROR(INDEX(University_Exit!$F:$F,MATCH($B232,University_Exit!$B:$B,0)),"") -> General Medicine | Q232: =IFERROR(INDEX(University_Exit!$L:$L,MATCH($B232,University_Exit!$B:$B,0)),"") -> Yes | R232: =IF(O232="","No","Yes") -> Yes | S232: =IFERROR(INDEX(University_Exit!$H:$H,MATCH($B232,University_Exit!$B:$B,0)),"") -> 94.69 | T232: =IFERROR(INDEX(University_Exit!$K:$K,MATCH($B232,University_Exit!$B:$B,0)),"") -> 1270 | U232: =IFERROR(INDEX(University_Exit!$G:$G,MATCH($B232,University_Exit!$B:$B,0)),"") -> 0

Sheet Baseline_Entry
A1: Cohort | B1: QID | C1: Student_Name | D1: Prior_School | E1: Curriculum | F1: English_Prior | G1: Science_Prior | H1: Math_Prior | I1: APTIS_Band | J1: APTIS_Score | K1: APTIS_% | L1: Math_Screening_Entry | M1: Math_% | N1: Baseline_CAT4_Overall | O1: CAT4_% | P1: Baseline_Composite | Q1: Profile | R1: Baseline_Verbal_SAS | S1: Baseline_Quantitative_SAS | T1: Baseline_Nonverbal_SAS | U1: Baseline_Spatial_SAS | V1: Assigned_Class | W1: Baseline_Source
A2: Class of 2022 | B2: 30463404774 | C2: حسن اسماعيل على العمادى | D2: =IFERROR(INDEX(Admissions_2024_2025!D:D,MATCH($B2,Admissions_2024_2025!$B:$B,0)),"") -> 0 | E2: =IFERROR(INDEX(Admissions_2024_2025!E:E,MATCH($B2,Admissions_2024_2025!$B:$B,0)),"") -> 0 | F2: =IFERROR(INDEX(Admissions_2024_2025!F:F,MATCH($B2,Admissions_2024_2025!$B:$B,0)),"") -> 46 | G2: =IFERROR(INDEX(Admissions_2024_2025!G:G,MATCH($B2,Admissions_2024_2025!$B:$B,0)),"") -> 68 | H2: =IFERROR(INDEX(Admissions_2024_2025!H:H,MATCH($B2,Admissions_2024_2025!$B:$B,0)),"") -> 80 | I2: =IFERROR(INDEX(Admissions_2024_2025!I:I,MATCH($B2,Admissions_2024_2025!$B:$B,0)),"") -> 0 | J2: =IFERROR(INDEX(Admissions_2024_2025!J:J,MATCH($B2,Admissions_2024_2025!$B:$B,0)),"") -> 115 | K2: =IF(J2="","",J2/250*100) -> 46 | L2: =IFERROR(INDEX(Admissions_2024_2025!L:L,MATCH($B2,Admissions_2024_2025!$B:$B,0)),"") -> 60 | M2: =IF(L2="","",L2/50*100) -> 120 | N2: =IF(COUNT(R2:U2)=0,"",ROUND(AVERAGE(R2:U2),0)) | O2: =IF(N2="","",N2/142*100) | P2: =IF(COUNT(K2,M2,O2)=0,"",AVERAGE(K2,M2,O2)) -> 83 | Q2: =IFERROR(INDEX(Admissions_2024_2025!Q:Q,MATCH($B2,Admissions_2024_2025!$B:$B,0)),"") | R2: =IFERROR(INDEX(Admissions_2024_2025!R:R,MATCH($B2,Admissions_2024_2025!$B:$B,0)),"") | S2: =IFERROR(INDEX(Admissions_2024_2025!S:S,MATCH($B2,Admissions_2024_2025!$B:$B,0)),"") | T2: =IFERROR(INDEX(Admissions_2024_2025!T:T,MATCH($B2,Admissions_2024_2025!$B:$B,0)),"") | U2: =IFERROR(INDEX(Admissions_2024_2025!U:U,MATCH($B2,Admissions_2024_2025!$B:$B,0)),"") | W2: =IFERROR(INDEX(Admissions_2024_2025!W:W,MATCH($B2,Admissions_2024_2025!$B:$B,0)),"") -> 2022 admissions (name-matched to QID); outcomes
A3: Class of 2022 | B3: 30463400105 | C3: سيف احمد محمد السليطى | D3: =IFERROR(INDEX(Admissions_2024_2025!D:D,MATCH($B3,Admissions_2024_2025!$B:$B,0)),"") -> 0 | E3: =IFERROR(INDEX(Admissions_2024_2025!E:E,MATCH($B3,Admissions_2024_2025!$B:$B,0)),"") -> 0 | F3: =IFERROR(INDEX(Admissions_2024_2025!F:F,MATCH($B3,Admissions_2024_2025!$B:$B,0)),"") -> 70.8 | G3: =IFERROR(INDEX(Admissions_2024_2025!G:G,MATCH($B3,Admissions_2024_2025!$B:$B,0)),"") -> 88 | H3: =IFERROR(INDEX(Admissions_2024_2025!H:H,MATCH($B3,Admissions_2024_2025!$B:$B,0)),"") -> 78.666667 | I3: =IFERROR(INDEX(Admissions_2024_2025!I:I,MATCH($B3,Admissions_2024_2025!$B:$B,0)),"") -> 0 | J3: =IFERROR(INDEX(Admissions_2024_2025!J:J,MATCH($B3,Admissions_2024_2025!$B:$B,0)),"") -> 177 | K3: =IF(J3="","",J3/250*100) -> 70.8 | L3: =IFERROR(INDEX(Admissions_2024_2025!L:L,MATCH($B3,Admissions_2024_2025!$B:$B,0)),"") -> 59 | M3: =IF(L3="","",L3/50*100) -> 118 | N3: =IF(COUNT(R3:U3)=0,"",ROUND(AVERAGE(R3:U3),0)) | O3: =IF(N3="","",N3/142*100) | P3: =IF(COUNT(K3,M3,O3)=0,"",AVERAGE(K3,M3,O3)) -> 94.4 | Q3: =IFERROR(INDEX(Admissions_2024_2025!Q:Q,MATCH($B3,Admissions_2024_2025!$B:$B,0)),"") | R3: =IFERROR(INDEX(Admissions_2024_2025!R:R,MATCH($B3,Admissions_2024_2025!$B:$B,0)),"") | S3: =IFERROR(INDEX(Admissions_2024_2025!S:S,MATCH($B3,Admissions_2024_2025!$B:$B,0)),"") | T3: =IFERROR(INDEX(Admissions_2024_2025!T:T,MATCH($B3,Admissions_2024_2025!$B:$B,0)),"") | U3: =IFERROR(INDEX(Admissions_2024_2025!U:U,MATCH($B3,Admissions_2024_2025!$B:$B,0)),"") | W3: =IFERROR(INDEX(Admissions_2024_2025!W:W,MATCH($B3,Admissions_2024_2025!$B:$B,0)),"") -> 2022 admissions (name-matched to QID); outcomes
A4: Class of 2022 | B4: 30463401069 | C4: سيف على ابراهيم المهندى | D4: =IFERROR(INDEX(Admissions_2024_2025!D:D,MATCH($B4,Admissions_2024_2025!$B:$B,0)),"") -> 0 | E4: =IFERROR(INDEX(Admissions_2024_2025!E:E,MATCH($B4,Admissions_2024_2025!$B:$B,0)),"") -> 0 | F4: =IFERROR(INDEX(Admissions_2024_2025!F:F,MATCH($B4,Admissions_2024_2025!$B:$B,0)),"") -> 56 | G4: =IFERROR(INDEX(Admissions_2024_2025!G:G,MATCH($B4,Admissions_2024_2025!$B:$B,0)),"") -> 72 | H4: =IFERROR(INDEX(Admissions_2024_2025!H:H,MATCH($B4,Admissions_2024_2025!$B:$B,0)),"") -> 72 | I4: =IFERROR(INDEX(Admissions_2024_2025!I:I,MATCH($B4,Admissions_2024_2025!$B:$B,0)),"") -> 0 | J4: =IFERROR(INDEX(Admissions_2024_2025!J:J,MATCH($B4,Admissions_2024_2025!$B:$B,0)),"") -> 140 | K4: =IF(J4="","",J4/250*100) -> 56 | L4: =IFERROR(INDEX(Admissions_2024_2025!L:L,MATCH($B4,Admissions_2024_2025!$B:$B,0)),"") -> 54 | M4: =IF(L4="","",L4/50*100) -> 108 | N4: =IF(COUNT(R4:U4)=0,"",ROUND(AVERAGE(R4:U4),0)) | O4: =IF(N4="","",N4/142*100) | P4: =IF(COUNT(K4,M4,O4)=0,"",AVERAGE(K4,M4,O4)) -> 82 | Q4: =IFERROR(INDEX(Admissions_2024_2025!Q:Q,MATCH($B4,Admissions_2024_2025!$B:$B,0)),"") | R4: =IFERROR(INDEX(Admissions_2024_2025!R:R,MATCH($B4,Admissions_2024_2025!$B:$B,0)),"") | S4: =IFERROR(INDEX(Admissions_2024_2025!S:S,MATCH($B4,Admissions_2024_2025!$B:$B,0)),"") | T4: =IFERROR(INDEX(Admissions_2024_2025!T:T,MATCH($B4,Admissions_2024_2025!$B:$B,0)),"") | U4: =IFERROR(INDEX(Admissions_2024_2025!U:U,MATCH($B4,Admissions_2024_2025!$B:$B,0)),"") | W4: =IFERROR(INDEX(Admissions_2024_2025!W:W,MATCH($B4,Admissions_2024_2025!$B:$B,0)),"") -> 2022 admissions (name-matched to QID); outcomes
A5: Class of 2022 | B5: 30463402074 | C5: عبدالرحمن عبدالعزيز اسماعيل الهاشمى | D5: =IFERROR(INDEX(Admissions_2024_2025!D:D,MATCH($B5,Admissions_2024_2025!$B:$B,0)),"") -> 0 | E5: =IFERROR(INDEX(Admissions_2024_2025!E:E,MATCH($B5,Admissions_2024_2025!$B:$B,0)),"") -> 0 | F5: =IFERROR(INDEX(Admissions_2024_2025!F:F,MATCH($B5,Admissions_2024_2025!$B:$B,0)),"") -> 54.4 | G5: =IFERROR(INDEX(Admissions_2024_2025!G:G,MATCH($B5,Admissions_2024_2025!$B:$B,0)),"") -> 84 | H5: =IFERROR(INDEX(Admissions_2024_2025!H:H,MATCH($B5,Admissions_2024_2025!$B:$B,0)),"") -> 69.333333 | I5: =IFERROR(INDEX(Admissions_2024_2025!I:I,MATCH($B5,Admissions_2024_2025!$B:$B,0)),"") -> 0 | J5: =IFERROR(INDEX(Admissions_2024_2025!J:J,MATCH($B5,Admissions_2024_2025!$B:$B,0)),"") -> 136 | K5: =IF(J5="","",J5/250*100) -> 54.4 | L5: =IFERROR(INDEX(Admissions_2024_2025!L:L,MATCH($B5,Admissions_2024_2025!$B:$B,0)),"") -> 52 | M5: =IF(L5="","",L5/50*100) -> 104 | N5: =IF(COUNT(R5:U5)=0,"",ROUND(AVERAGE(R5:U5),0)) | O5: =IF(N5="","",N5/142*100) | P5: =IF(COUNT(K5,M5,O5)=0,"",AVERAGE(K5,M5,O5)) -> 79.2 | Q5: =IFERROR(INDEX(Admissions_2024_2025!Q:Q,MATCH($B5,Admissions_2024_2025!$B:$B,0)),"") | R5: =IFERROR(INDEX(Admissions_2024_2025!R:R,MATCH($B5,Admissions_2024_2025!$B:$B,0)),"") | S5: =IFERROR(INDEX(Admissions_2024_2025!S:S,MATCH($B5,Admissions_2024_2025!$B:$B,0)),"") | T5: =IFERROR(INDEX(Admissions_2024_2025!T:T,MATCH($B5,Admissions_2024_2025!$B:$B,0)),"") | U5: =IFERROR(INDEX(Admissions_2024_2025!U:U,MATCH($B5,Admissions_2024_2025!$B:$B,0)),"") | W5: =IFERROR(INDEX(Admissions_2024_2025!W:W,MATCH($B5,Admissions_2024_2025!$B:$B,0)),"") -> 2022 admissions (name-matched to QID); outcomes
A6: Class of 2022 | B6: 30463400747 | C6: عبدالرحمن عبدالله عزالدين المطوع | D6: =IFERROR(INDEX(Admissions_2024_2025!D:D,MATCH($B6,Admissions_2024_2025!$B:$B,0)),"") -> 0 | E6: =IFERROR(INDEX(Admissions_2024_2025!E:E,MATCH($B6,Admissions_2024_2025!$B:$B,0)),"") -> 0 | F6: =IFERROR(INDEX(Admissions_2024_2025!F:F,MATCH($B6,Admissions_2024_2025!$B:$B,0)),"") -> 59.2 | G6: =IFERROR(INDEX(Admissions_2024_2025!G:G,MATCH($B6,Admissions_2024_2025!$B:$B,0)),"") -> 80 | H6: =IFERROR(INDEX(Admissions_2024_2025!H:H,MATCH($B6,Admissions_2024_2025!$B:$B,0)),"") -> 76 | I6: =IFERROR(INDEX(Admissions_2024_2025!I:I,MATCH($B6,Admissions_2024_2025!$B:$B,0)),"") -> 0 | J6: =IFERROR(INDEX(Admissions_2024_2025!J:J,MATCH($B6,Admissions_2024_2025!$B:$B,0)),"") -> 148 | K6: =IF(J6="","",J6/250*100) -> 59.2 | L6: =IFERROR(INDEX(Admissions_2024_2025!L:L,MATCH($B6,Admissions_2024_2025!$B:$B,0)),"") -> 57 | M6: =IF(L6="","",L6/50*100) -> 114 | N6: =IF(COUNT(R6:U6)=0,"",ROUND(AVERAGE(R6:U6),0)) | O6: =IF(N6="","",N6/142*100) | P6: =IF(COUNT(K6,M6,O6)=0,"",AVERAGE(K6,M6,O6)) -> 86.6 | Q6: =IFERROR(INDEX(Admissions_2024_2025!Q:Q,MATCH($B6,Admissions_2024_2025!$B:$B,0)),"") | R6: =IFERROR(INDEX(Admissions_2024_2025!R:R,MATCH($B6,Admissions_2024_2025!$B:$B,0)),"") | S6: =IFERROR(INDEX(Admissions_2024_2025!S:S,MATCH($B6,Admissions_2024_2025!$B:$B,0)),"") | T6: =IFERROR(INDEX(Admissions_2024_2025!T:T,MATCH($B6,Admissions_2024_2025!$B:$B,0)),"") | U6: =IFERROR(INDEX(Admissions_2024_2025!U:U,MATCH($B6,Admissions_2024_2025!$B:$B,0)),"") | W6: =IFERROR(INDEX(Admissions_2024_2025!W:W,MATCH($B6,Admissions_2024_2025!$B:$B,0)),"") -> 2022 admissions (name-matched to QID); outcomes
A7: Class of 2022 | B7: 30463402384 | C7: عبدالرحمن محمد سعد السليطى | D7: =IFERROR(INDEX(Admissions_2024_2025!D:D,MATCH($B7,Admissions_2024_2025!$B:$B,0)),"") -> 0 | E7: =IFERROR(INDEX(Admissions_2024_2025!E:E,MATCH($B7,Admissions_2024_2025!$B:$B,0)),"") -> 0 | F7: =IFERROR(INDEX(Admissions_2024_2025!F:F,MATCH($B7,Admissions_2024_2025!$B:$B,0)),"") -> 67.2 | G7: =IFERROR(INDEX(Admissions_2024_2025!G:G,MATCH($B7,Admissions_2024_2025!$B:$B,0)),"") -> 96 | H7: =IFERROR(INDEX(Admissions_2024_2025!H:H,MATCH($B7,Admissions_2024_2025!$B:$B,0)),"") -> 54.666667 | I7: =IFERROR(INDEX(Admissions_2024_2025!I:I,MATCH($B7,Admissions_2024_2025!$B:$B,0)),"") -> 0 | J7: =IFERROR(INDEX(Admissions_2024_2025!J:J,MATCH($B7,Admissions_2024_2025!$B:$B,0)),"") -> 168 | K7: =IF(J7="","",J7/250*100) -> 67.2 | L7: =IFERROR(INDEX(Admissions_2024_2025!L:L,MATCH($B7,Admissions_2024_2025!$B:$B,0)),"") -> 41 | M7: =IF(L7="","",L7/50*100) -> 82 | N7: =IF(COUNT(R7:U7)=0,"",ROUND(AVERAGE(R7:U7),0)) | O7: =IF(N7="","",N7/142*100) | P7: =IF(COUNT(K7,M7,O7)=0,"",AVERAGE(K7,M7,O7)) -> 74.6 | Q7: =IFERROR(INDEX(Admissions_2024_2025!Q:Q,MATCH($B7,Admissions_2024_2025!$B:$B,0)),"") | R7: =IFERROR(INDEX(Admissions_2024_2025!R:R,MATCH($B7,Admissions_2024_2025!$B:$B,0)),"") | S7: =IFERROR(INDEX(Admissions_2024_2025!S:S,MATCH($B7,Admissions_2024_2025!$B:$B,0)),"") | T7: =IFERROR(INDEX(Admissions_2024_2025!T:T,MATCH($B7,Admissions_2024_2025!$B:$B,0)),"") | U7: =IFERROR(INDEX(Admissions_2024_2025!U:U,MATCH($B7,Admissions_2024_2025!$B:$B,0)),"") | W7: =IFERROR(INDEX(Admissions_2024_2025!W:W,MATCH($B7,Admissions_2024_2025!$B:$B,0)),"") -> 2022 admissions (name-matched to QID); outcomes
A8: Class of 2022 | B8: 30363404443 | C8: عبدالعزيز صلاح على الانشائى | D8: =IFERROR(INDEX(Admissions_2024_2025!D:D,MATCH($B8,Admissions_2024_2025!$B:$B,0)),"") -> 0 | E8: =IFERROR(INDEX(Admissions_2024_2025!E:E,MATCH($B8,Admissions_2024_2025!$B:$B,0)),"") -> 0 | F8: =IFERROR(INDEX(Admissions_2024_2025!F:F,MATCH($B8,Admissions_2024_2025!$B:$B,0)),"") -> 58.4 | G8: =IFERROR(INDEX(Admissions_2024_2025!G:G,MATCH($B8,Admissions_2024_2025!$B:$B,0)),"") -> 88 | H8: =IFERROR(INDEX(Admissions_2024_2025!H:H,MATCH($B8,Admissions_2024_2025!$B:$B,0)),"") -> 62.666667 | I8: =IFERROR(INDEX(Admissions_2024_2025!I:I,MATCH($B8,Admissions_2024_2025!$B:$B,0)),"") -> 0 | J8: =IFERROR(INDEX(Admissions_2024_2025!J:J,MATCH($B8,Admissions_2024_2025!$B:$B,0)),"") -> 146 | K8: =IF(J8="","",J8/250*100) -> 58.4 | L8: =IFERROR(INDEX(Admissions_2024_2025!L:L,MATCH($B8,Admissions_2024_2025!$B:$B,0)),"") -> 47 | M8: =IF(L8="","",L8/50*100) -> 94 | N8: =IF(COUNT(R8:U8)=0,"",ROUND(AVERAGE(R8:U8),0)) | O8: =IF(N8="","",N8/142*100) | P8: =IF(COUNT(K8,M8,O8)=0,"",AVERAGE(K8,M8,O8)) -> 76.2 | Q8: =IFERROR(INDEX(Admissions_2024_2025!Q:Q,MATCH($B8,Admissions_2024_2025!$B:$B,0)),"") | R8: =IFERROR(INDEX(Admissions_2024_2025!R:R,MATCH($B8,Admissions_2024_2025!$B:$B,0)),"") | S8: =IFERROR(INDEX(Admissions_2024_2025!S:S,MATCH($B8,Admissions_2024_2025!$B:$B,0)),"") | T8: =IFERROR(INDEX(Admissions_2024_2025!T:T,MATCH($B8,Admissions_2024_2025!$B:$B,0)),"") | U8: =IFERROR(INDEX(Admissions_2024_2025!U:U,MATCH($B8,Admissions_2024_2025!$B:$B,0)),"") | W8: =IFERROR(INDEX(Admissions_2024_2025!W:W,MATCH($B8,Admissions_2024_2025!$B:$B,0)),"") -> 2022 admissions (name-matched to QID); outcomes
A9: Class of 2022 | B9: 30463404428 | C9: عبدالعزيز على يوسف التميمى | D9: =IFERROR(INDEX(Admissions_2024_2025!D:D,MATCH($B9,Admissions_2024_2025!$B:$B,0)),"") -> 0 | E9: =IFERROR(INDEX(Admissions_2024_2025!E:E,MATCH($B9,Admissions_2024_2025!$B:$B,0)),"") -> 0 | F9: =IFERROR(INDEX(Admissions_2024_2025!F:F,MATCH($B9,Admissions_2024_2025!$B:$B,0)),"") -> 57.6 | G9: =IFERROR(INDEX(Admissions_2024_2025!G:G,MATCH($B9,Admissions_2024_2025!$B:$B,0)),"") -> 88 | H9: =IFERROR(INDEX(Admissions_2024_2025!H:H,MATCH($B9,Admissions_2024_2025!$B:$B,0)),"") -> 74.666667 | I9: =IFERROR(INDEX(Admissions_2024_2025!I:I,MATCH($B9,Admissions_2024_2025!$B:$B,0)),"") -> 0 | J9: =IFERROR(INDEX(Admissions_2024_2025!J:J,MATCH($B9,Admissions_2024_2025!$B:$B,0)),"") -> 144 | K9: =IF(J9="","",J9/250*100) -> 57.6 | L9: =IFERROR(INDEX(Admissions_2024_2025!L:L,MATCH($B9,Admissions_2024_2025!$B:$B,0)),"") -> 56 | M9: =IF(L9="","",L9/50*100) -> 112 | N9: =IF(COUNT(R9:U9)=0,"",ROUND(AVERAGE(R9:U9),0)) | O9: =IF(N9="","",N9/142*100) | P9: =IF(COUNT(K9,M9,O9)=0,"",AVERAGE(K9,M9,O9)) -> 84.8 | Q9: =IFERROR(INDEX(Admissions_2024_2025!Q:Q,MATCH($B9,Admissions_2024_2025!$B:$B,0)),"") | R9: =IFERROR(INDEX(Admissions_2024_2025!R:R,MATCH($B9,Admissions_2024_2025!$B:$B,0)),"") | S9: =IFERROR(INDEX(Admissions_2024_2025!S:S,MATCH($B9,Admissions_2024_2025!$B:$B,0)),"") | T9: =IFERROR(INDEX(Admissions_2024_2025!T:T,MATCH($B9,Admissions_2024_2025!$B:$B,0)),"") | U9: =IFERROR(INDEX(Admissions_2024_2025!U:U,MATCH($B9,Admissions_2024_2025!$B:$B,0)),"") | W9: =IFERROR(INDEX(Admissions_2024_2025!W:W,MATCH($B9,Admissions_2024_2025!$B:$B,0)),"") -> 2022 admissions (name-matched to QID); outcomes
A10: Class of 2022 | B10: 30463400925 | C10: عبدالله خالد احمد النصر | D10: =IFERROR(INDEX(Admissions_2024_2025!D:D,MATCH($B10,Admissions_2024_2025!$B:$B,0)),"") -> 0 | E10: =IFERROR(INDEX(Admissions_2024_2025!E:E,MATCH($B10,Admissions_2024_2025!$B:$B,0)),"") -> 0 | F10: =IFERROR(INDEX(Admissions_2024_2025!F:F,MATCH($B10,Admissions_2024_2025!$B:$B,0)),"") -> 66 | G10: =IFERROR(INDEX(Admissions_2024_2025!G:G,MATCH($B10,Admissions_2024_2025!$B:$B,0)),"") -> 96 | H10: =IFERROR(INDEX(Admissions_2024_2025!H:H,MATCH($B10,Admissions_2024_2025!$B:$B,0)),"") -> 74.666667 | I10: =IFERROR(INDEX(Admissions_2024_2025!I:I,MATCH($B10,Admissions_2024_2025!$B:$B,0)),"") -> 0 | J10: =IFERROR(INDEX(Admissions_2024_2025!J:J,MATCH($B10,Admissions_2024_2025!$B:$B,0)),"") -> 165 | K10: =IF(J10="","",J10/250*100) -> 66 | L10: =IFERROR(INDEX(Admissions_2024_2025!L:L,MATCH($B10,Admissions_2024_2025!$B:$B,0)),"") -> 56 | M10: =IF(L10="","",L10/50*100) -> 112 | N10: =IF(COUNT(R10:U10)=0,"",ROUND(AVERAGE(R10:U10),0)) | O10: =IF(N10="","",N10/142*100) | P10: =IF(COUNT(K10,M10,O10)=0,"",AVERAGE(K10,M10,O10)) -> 89 | Q10: =IFERROR(INDEX(Admissions_2024_2025!Q:Q,MATCH($B10,Admissions_2024_2025!$B:$B,0)),"") | R10: =IFERROR(INDEX(Admissions_2024_2025!R:R,MATCH($B10,Admissions_2024_2025!$B:$B,0)),"") | S10: =IFERROR(INDEX(Admissions_2024_2025!S:S,MATCH($B10,Admissions_2024_2025!$B:$B,0)),"") | T10: =IFERROR(INDEX(Admissions_2024_2025!T:T,MATCH($B10,Admissions_2024_2025!$B:$B,0)),"") | U10: =IFERROR(INDEX(Admissions_2024_2025!U:U,MATCH($B10,Admissions_2024_2025!$B:$B,0)),"") | W10: =IFERROR(INDEX(Admissions_2024_2025!W:W,MATCH($B10,Admissions_2024_2025!$B:$B,0)),"") -> 2022 admissions (name-matched to QID); outcomes
A11: Class of 2022 | B11: 30463404499 | C11: عبدالله على راشد النجدى | D11: =IFERROR(INDEX(Admissions_2024_2025!D:D,MATCH($B11,Admissions_2024_2025!$B:$B,0)),"") -> 0 | E11: =IFERROR(INDEX(Admissions_2024_2025!E:E,MATCH($B11,Admissions_2024_2025!$B:$B,0)),"") -> 0 | F11: =IFERROR(INDEX(Admissions_2024_2025!F:F,MATCH($B11,Admissions_2024_2025!$B:$B,0)),"") -> 0 | G11: =IFERROR(INDEX(Admissions_2024_2025!G:G,MATCH($B11,Admissions_2024_2025!$B:$B,0)),"") -> 96 | H11: =IFERROR(INDEX(Admissions_2024_2025!H:H,MATCH($B11,Admissions_2024_2025!$B:$B,0)),"") -> 72 | I11: =IFERROR(INDEX(Admissions_2024_2025!I:I,MATCH($B11,Admissions_2024_2025!$B:$B,0)),"") -> 0 | J11: =IFERROR(INDEX(Admissions_2024_2025!J:J,MATCH($B11,Admissions_2024_2025!$B:$B,0)),"") -> 0 | K11: =IF(J11="","",J11/250*100) -> 0 | L11: =IFERROR(INDEX(Admissions_2024_2025!L:L,MATCH($B11,Admissions_2024_2025!$B:$B,0)),"") -> 54 | M11: =IF(L11="","",L11/50*100) -> 108 | N11: =IF(COUNT(R11:U11)=0,"",ROUND(AVERAGE(R11:U11),0)) | O11: =IF(N11="","",N11/142*100) | P11: =IF(COUNT(K11,M11,O11)=0,"",AVERAGE(K11,M11,O11)) -> 54 | Q11: =IFERROR(INDEX(Admissions_2024_2025!Q:Q,MATCH($B11,Admissions_2024_2025!$B:$B,0)),"") | R11: =IFERROR(INDEX(Admissions_2024_2025!R:R,MATCH($B11,Admissions_2024_2025!$B:$B,0)),"") | S11: =IFERROR(INDEX(Admissions_2024_2025!S:S,MATCH($B11,Admissions_2024_2025!$B:$B,0)),"") | T11: =IFERROR(INDEX(Admissions_2024_2025!T:T,MATCH($B11,Admissions_2024_2025!$B:$B,0)),"") | U11: =IFERROR(INDEX(Admissions_2024_2025!U:U,MATCH($B11,Admissions_2024_2025!$B:$B,0)),"") | W11: =IFERROR(INDEX(Admissions_2024_2025!W:W,MATCH($B11,Admissions_2024_2025!$B:$B,0)),"") -> 2022 admissions (name-matched to QID); outcomes
A12: Class of 2022 | B12: 30463404313 | C12: غانم عبدالله سالم المرى | D12: =IFERROR(INDEX(Admissions_2024_2025!D:D,MATCH($B12,Admissions_2024_2025!$B:$B,0)),"") -> 0 | E12: =IFERROR(INDEX(Admissions_2024_2025!E:E,MATCH($B12,Admissions_2024_2025!$B:$B,0)),"") -> 0 | F12: =IFERROR(INDEX(Admissions_2024_2025!F:F,MATCH($B12,Admissions_2024_2025!$B:$B,0)),"") -> 62 | G12: =IFERROR(INDEX(Admissions_2024_2025!G:G,MATCH($B12,Admissions_2024_2025!$B:$B,0)),"") -> 92 | H12: =IFERROR(INDEX(Admissions_2024_2025!H:H,MATCH($B12,Admissions_2024_2025!$B:$B,0)),"") -> 60 | I12: =IFERROR(INDEX(Admissions_2024_2025!I:I,MATCH($B12,Admissions_2024_2025!$B:$B,0)),"") -> 0 | J12: =IFERROR(INDEX(Admissions_2024_2025!J:J,MATCH($B12,Admissions_2024_2025!$B:$B,0)),"") -> 155 | K12: =IF(J12="","",J12/250*100) -> 62 | L12: =IFERROR(INDEX(Admissions_2024_2025!L:L,MATCH($B12,Admissions_2024_2025!$B:$B,0)),"") -> 45 | M12: =IF(L12="","",L12/50*100) -> 90 | N12: =IF(COUNT(R12:U12)=0,"",ROUND(AVERAGE(R12:U12),0)) | O12: =IF(N12="","",N12/142*100) | P12: =IF(COUNT(K12,M12,O12)=0,"",AVERAGE(K12,M12,O12)) -> 76 | Q12: =IFERROR(INDEX(Admissions_2024_2025!Q:Q,MATCH($B12,Admissions_2024_2025!$B:$B,0)),"") | R12: =IFERROR(INDEX(Admissions_2024_2025!R:R,MATCH($B12,Admissions_2024_2025!$B:$B,0)),"") | S12: =IFERROR(INDEX(Admissions_2024_2025!S:S,MATCH($B12,Admissions_2024_2025!$B:$B,0)),"") | T12: =IFERROR(INDEX(Admissions_2024_2025!T:T,MATCH($B12,Admissions_2024_2025!$B:$B,0)),"") | U12: =IFERROR(INDEX(Admissions_2024_2025!U:U,MATCH($B12,Admissions_2024_2025!$B:$B,0)),"") | W12: =IFERROR(INDEX(Admissions_2024_2025!W:W,MATCH($B12,Admissions_2024_2025!$B:$B,0)),"") -> 2022 admissions (name-matched to QID); outcomes
A13: Class of 2022 | B13: 30463401470 | C13: ماجد عبدالله ماجد السويدى | D13: =IFERROR(INDEX(Admissions_2024_2025!D:D,MATCH($B13,Admissions_2024_2025!$B:$B,0)),"") -> 0 | E13: =IFERROR(INDEX(Admissions_2024_2025!E:E,MATCH($B13,Admissions_2024_2025!$B:$B,0)),"") -> 0 | F13: =IFERROR(INDEX(Admissions_2024_2025!F:F,MATCH($B13,Admissions_2024_2025!$B:$B,0)),"") -> 43.6 | G13: =IFERROR(INDEX(Admissions_2024_2025!G:G,MATCH($B13,Admissions_2024_2025!$B:$B,0)),"") -> 56 | H13: =IFERROR(INDEX(Admissions_2024_2025!H:H,MATCH($B13,Admissions_2024_2025!$B:$B,0)),"") -> 74.666667 | I13: =IFERROR(INDEX(Admissions_2024_2025!I:I,MATCH($B13,Admissions_2024_2025!$B:$B,0)),"") -> 0 | J13: =IFERROR(INDEX(Admissions_2024_2025!J:J,MATCH($B13,Admissions_2024_2025!$B:$B,0)),"") -> 109 | K13: =IF(J13="","",J13/250*100) -> 43.6 | L13: =IFERROR(INDEX(Admissions_2024_2025!L:L,MATCH($B13,Admissions_2024_2025!$B:$B,0)),"") -> 56 | M13: =IF(L13="","",L13/50*100) -> 112 | N13: =IF(COUNT(R13:U13)=0,"",ROUND(AVERAGE(R13:U13),0)) | O13: =IF(N13="","",N13/142*100) | P13: =IF(COUNT(K13,M13,O13)=0,"",AVERAGE(K13,M13,O13)) -> 77.8 | Q13: =IFERROR(INDEX(Admissions_2024_2025!Q:Q,MATCH($B13,Admissions_2024_2025!$B:$B,0)),"") | R13: =IFERROR(INDEX(Admissions_2024_2025!R:R,MATCH($B13,Admissions_2024_2025!$B:$B,0)),"") | S13: =IFERROR(INDEX(Admissions_2024_2025!S:S,MATCH($B13,Admissions_2024_2025!$B:$B,0)),"") | T13: =IFERROR(INDEX(Admissions_2024_2025!T:T,MATCH($B13,Admissions_2024_2025!$B:$B,0)),"") | U13: =IFERROR(INDEX(Admissions_2024_2025!U:U,MATCH($B13,Admissions_2024_2025!$B:$B,0)),"") | W13: =IFERROR(INDEX(Admissions_2024_2025!W:W,MATCH($B13,Admissions_2024_2025!$B:$B,0)),"") -> 2022 admissions (name-matched to QID); outcomes
... A60: Class of 2022 | B60: 30463403015 | C60: نصار طارق حسين نصار | D60: =IFERROR(INDEX(Admissions_2024_2025!D:D,MATCH($B60,Admissions_2024_2025!$B:$B,0)),"") -> 0 | E60: =IFERROR(INDEX(Admissions_2024_2025!E:E,MATCH($B60,Admissions_2024_2025!$B:$B,0)),"") -> 0 | F60: =IFERROR(INDEX(Admissions_2024_2025!F:F,MATCH($B60,Admissions_2024_2025!$B:$B,0)),"") -> 58 | G60: =IFERROR(INDEX(Admissions_2024_2025!G:G,MATCH($B60,Admissions_2024_2025!$B:$B,0)),"") -> 100 | H60: =IFERROR(INDEX(Admissions_2024_2025!H:H,MATCH($B60,Admissions_2024_2025!$B:$B,0)),"") -> 70.666667 | I60: =IFERROR(INDEX(Admissions_2024_2025!I:I,MATCH($B60,Admissions_2024_2025!$B:$B,0)),"") -> 0 | J60: =IFERROR(INDEX(Admissions_2024_2025!J:J,MATCH($B60,Admissions_2024_2025!$B:$B,0)),"") -> 145 | K60: =IF(J60="","",J60/250*100) -> 58 | L60: =IFERROR(INDEX(Admissions_2024_2025!L:L,MATCH($B60,Admissions_2024_2025!$B:$B,0)),"") -> 53 | M60: =IF(L60="","",L60/50*100) -> 106 | N60: =IF(COUNT(R60:U60)=0,"",ROUND(AVERAGE(R60:U60),0)) | O60: =IF(N60="","",N60/142*100) | P60: =IF(COUNT(K60,M60,O60)=0,"",AVERAGE(K60,M60,O60)) -> 82 | Q60: =IFERROR(INDEX(Admissions_2024_2025!Q:Q,MATCH($B60,Admissions_2024_2025!$B:$B,0)),"") | R60: =IFERROR(INDEX(Admissions_2024_2025!R:R,MATCH($B60,Admissions_2024_2025!$B:$B,0)),"") | S60: =IFERROR(INDEX(Admissions_2024_2025!S:S,MATCH($B60,Admissions_2024_2025!$B:$B,0)),"") | T60: =IFERROR(INDEX(Admissions_2024_2025!T:T,MATCH($B60,Admissions_2024_2025!$B:$B,0)),"") | U60: =IFERROR(INDEX(Admissions_2024_2025!U:U,MATCH($B60,Admissions_2024_2025!$B:$B,0)),"") | W60: =IFERROR(INDEX(Admissions_2024_2025!W:W,MATCH($B60,Admissions_2024_2025!$B:$B,0)),"") -> 2022 admissions (name-matched to QID); outcomes
A61: Class of 2023 | B61: 30563405617 | C61: ابراهيم احمد ابراهيم البدر | D61: =IFERROR(INDEX(Admissions_2024_2025!D:D,MATCH($B61,Admissions_2024_2025!$B:$B,0)),"") -> Umar ibn Al-Khattab Preparatory School for Boys | E61: =IFERROR(INDEX(Admissions_2024_2025!E:E,MATCH($B61,Admissions_2024_2025!$B:$B,0)),"") -> General | F61: =IFERROR(INDEX(Admissions_2024_2025!F:F,MATCH($B61,Admissions_2024_2025!$B:$B,0)),"") -> 92 | G61: =IFERROR(INDEX(Admissions_2024_2025!G:G,MATCH($B61,Admissions_2024_2025!$B:$B,0)),"") -> 0 | H61: =IFERROR(INDEX(Admissions_2024_2025!H:H,MATCH($B61,Admissions_2024_2025!$B:$B,0)),"") -> 0 | I61: =IFERROR(INDEX(Admissions_2024_2025!I:I,MATCH($B61,Admissions_2024_2025!$B:$B,0)),"") -> B1 | J61: =IFERROR(INDEX(Admissions_2024_2025!J:J,MATCH($B61,Admissions_2024_2025!$B:$B,0)),"") -> 112 | K61: =IF(J61="","",J61/250*100) -> 44.8 | L61: =IFERROR(INDEX(Admissions_2024_2025!L:L,MATCH($B61,Admissions_2024_2025!$B:$B,0)),"") -> 63 | M61: =IF(L61="","",L61/50*100) -> 126 | N61: =IF(COUNT(R61:U61)=0,"",ROUND(AVERAGE(R61:U61),0)) -> 105 | O61: =IF(N61="","",N61/142*100) -> 73.943662 | P61: =IF(COUNT(K61,M61,O61)=0,"",AVERAGE(K61,M61,O61)) -> 81.581221 | Q61: =IFERROR(INDEX(Admissions_2024_2025!Q:Q,MATCH($B61,Admissions_2024_2025!$B:$B,0)),"") -> Moderate spatial bias | R61: =IFERROR(INDEX(Admissions_2024_2025!R:R,MATCH($B61,Admissions_2024_2025!$B:$B,0)),"") -> 86 | S61: =IFERROR(INDEX(Admissions_2024_2025!S:S,MATCH($B61,Admissions_2024_2025!$B:$B,0)),"") -> 116 | T61: =IFERROR(INDEX(Admissions_2024_2025!T:T,MATCH($B61,Admissions_2024_2025!$B:$B,0)),"") -> 111 | U61: =IFERROR(INDEX(Admissions_2024_2025!U:U,MATCH($B61,Admissions_2024_2025!$B:$B,0)),"") -> 107 | V61: =IFERROR(INDEX(Admissions_2024_2025!V:V,MATCH($B2,Admissions_2024_2025!$B:$B,0)),"") -> 0 | W61: =IFERROR(INDEX(Admissions_2024_2025!W:W,MATCH($B61,Admissions_2024_2025!$B:$B,0)),"") -> 2023 admissions; 2019 accepted list; CAT new students
A62: Class of 2023 | B62: 30563400001 | C62: جاسم محمد دغش الدوسرى | D62: =IFERROR(INDEX(Admissions_2024_2025!D:D,MATCH($B62,Admissions_2024_2025!$B:$B,0)),"") -> Doha Preparatory School for Boys | E62: =IFERROR(INDEX(Admissions_2024_2025!E:E,MATCH($B62,Admissions_2024_2025!$B:$B,0)),"") -> General | F62: =IFERROR(INDEX(Admissions_2024_2025!F:F,MATCH($B62,Admissions_2024_2025!$B:$B,0)),"") -> 96 | G62: =IFERROR(INDEX(Admissions_2024_2025!G:G,MATCH($B62,Admissions_2024_2025!$B:$B,0)),"") -> 0 | H62: =IFERROR(INDEX(Admissions_2024_2025!H:H,MATCH($B62,Admissions_2024_2025!$B:$B,0)),"") -> 0 | I62: =IFERROR(INDEX(Admissions_2024_2025!I:I,MATCH($B62,Admissions_2024_2025!$B:$B,0)),"") -> B1 | J62: =IFERROR(INDEX(Admissions_2024_2025!J:J,MATCH($B62,Admissions_2024_2025!$B:$B,0)),"") -> 127 | K62: =IF(J62="","",J62/250*100) -> 50.8 | L62: =IFERROR(INDEX(Admissions_2024_2025!L:L,MATCH($B62,Admissions_2024_2025!$B:$B,0)),"") -> 75 | M62: =IF(L62="","",L62/50*100) -> 150 | N62: =IF(COUNT(R62:U62)=0,"",ROUND(AVERAGE(R62:U62),0)) -> 107 | O62: =IF(N62="","",N62/142*100) -> 75.352113 | P62: =IF(COUNT(K62,M62,O62)=0,"",AVERAGE(K62,M62,O62)) -> 92.050704 | Q62: =IFERROR(INDEX(Admissions_2024_2025!Q:Q,MATCH($B62,Admissions_2024_2025!$B:$B,0)),"") -> Extreme spatial bias | R62: =IFERROR(INDEX(Admissions_2024_2025!R:R,MATCH($B62,Admissions_2024_2025!$B:$B,0)),"") -> 75 | S62: =IFERROR(INDEX(Admissions_2024_2025!S:S,MATCH($B62,Admissions_2024_2025!$B:$B,0)),"") -> 112 | T62: =IFERROR(INDEX(Admissions_2024_2025!T:T,MATCH($B62,Admissions_2024_2025!$B:$B,0)),"") -> 121 | U62: =IFERROR(INDEX(Admissions_2024_2025!U:U,MATCH($B62,Admissions_2024_2025!$B:$B,0)),"") -> 118 | V62: =IFERROR(INDEX(Admissions_2024_2025!V:V,MATCH($B3,Admissions_2024_2025!$B:$B,0)),"") -> 0 | W62: =IFERROR(INDEX(Admissions_2024_2025!W:W,MATCH($B62,Admissions_2024_2025!$B:$B,0)),"") -> 2023 admissions; 2019 accepted list; CAT new students
A63: Class of 2023 | B63: 30563403466 | C63: حارب طارق حارب المهندى | D63: =IFERROR(INDEX(Admissions_2024_2025!D:D,MATCH($B63,Admissions_2024_2025!$B:$B,0)),"") -> Abu Bakr as-Siddiq Preparatory School for Boys | E63: =IFERROR(INDEX(Admissions_2024_2025!E:E,MATCH($B63,Admissions_2024_2025!$B:$B,0)),"") -> General | F63: =IFERROR(INDEX(Admissions_2024_2025!F:F,MATCH($B63,Admissions_2024_2025!$B:$B,0)),"") -> 91 | G63: =IFERROR(INDEX(Admissions_2024_2025!G:G,MATCH($B63,Admissions_2024_2025!$B:$B,0)),"") -> 0 | H63: =IFERROR(INDEX(Admissions_2024_2025!H:H,MATCH($B63,Admissions_2024_2025!$B:$B,0)),"") -> 0 | I63: =IFERROR(INDEX(Admissions_2024_2025!I:I,MATCH($B63,Admissions_2024_2025!$B:$B,0)),"") -> B2 | J63: =IFERROR(INDEX(Admissions_2024_2025!J:J,MATCH($B63,Admissions_2024_2025!$B:$B,0)),"") -> 136 | K63: =IF(J63="","",J63/250*100) -> 54.4 | L63: =IFERROR(INDEX(Admissions_2024_2025!L:L,MATCH($B63,Admissions_2024_2025!$B:$B,0)),"") -> 40 | M63: =IF(L63="","",L63/50*100) -> 80 | N63: =IF(COUNT(R63:U63)=0,"",ROUND(AVERAGE(R63:U63),0)) -> 93 | O63: =IF(N63="","",N63/142*100) -> 65.492958 | P63: =IF(COUNT(K63,M63,O63)=0,"",AVERAGE(K63,M63,O63)) -> 66.630986 | Q63: =IFERROR(INDEX(Admissions_2024_2025!Q:Q,MATCH($B63,Admissions_2024_2025!$B:$B,0)),"") -> No bias | R63: =IFERROR(INDEX(Admissions_2024_2025!R:R,MATCH($B63,Admissions_2024_2025!$B:$B,0)),"") -> 85 | S63: =IFERROR(INDEX(Admissions_2024_2025!S:S,MATCH($B63,Admissions_2024_2025!$B:$B,0)),"") -> 101 | T63: =IFERROR(INDEX(Admissions_2024_2025!T:T,MATCH($B63,Admissions_2024_2025!$B:$B,0)),"") -> 93 | U63: =IFERROR(INDEX(Admissions_2024_2025!U:U,MATCH($B63,Admissions_2024_2025!$B:$B,0)),"") -> 94 | V63: =IFERROR(INDEX(Admissions_2024_2025!V:V,MATCH($B4,Admissions_2024_2025!$B:$B,0)),"") -> 0 | W63: =IFERROR(INDEX(Admissions_2024_2025!W:W,MATCH($B63,Admissions_2024_2025!$B:$B,0)),"") -> 2023 admissions; 2019 accepted list; CAT new students
A64: Class of 2023 | B64: 30563405656 | C64: سلطان حسن احمد ابوهندى | D64: =IFERROR(INDEX(Admissions_2024_2025!D:D,MATCH($B64,Admissions_2024_2025!$B:$B,0)),"") -> Abu Bakr as-Siddiq Preparatory School for Boys | E64: =IFERROR(INDEX(Admissions_2024_2025!E:E,MATCH($B64,Admissions_2024_2025!$B:$B,0)),"") -> General | F64: =IFERROR(INDEX(Admissions_2024_2025!F:F,MATCH($B64,Admissions_2024_2025!$B:$B,0)),"") -> 95 | G64: =IFERROR(INDEX(Admissions_2024_2025!G:G,MATCH($B64,Admissions_2024_2025!$B:$B,0)),"") -> 0 | H64: =IFERROR(INDEX(Admissions_2024_2025!H:H,MATCH($B64,Admissions_2024_2025!$B:$B,0)),"") -> 0 | I64: =IFERROR(INDEX(Admissions_2024_2025!I:I,MATCH($B64,Admissions_2024_2025!$B:$B,0)),"") -> B1 | J64: =IFERROR(INDEX(Admissions_2024_2025!J:J,MATCH($B64,Admissions_2024_2025!$B:$B,0)),"") -> 140 | K64: =IF(J64="","",J64/250*100) -> 56 | L64: =IFERROR(INDEX(Admissions_2024_2025!L:L,MATCH($B64,Admissions_2024_2025!$B:$B,0)),"") -> 83 | M64: =IF(L64="","",L64/50*100) -> 166 | N64: =IF(COUNT(R64:U64)=0,"",ROUND(AVERAGE(R64:U64),0)) -> 96 | O64: =IF(N64="","",N64/142*100) -> 67.605634 | P64: =IF(COUNT(K64,M64,O64)=0,"",AVERAGE(K64,M64,O64)) -> 96.535211 | Q64: =IFERROR(INDEX(Admissions_2024_2025!Q:Q,MATCH($B64,Admissions_2024_2025!$B:$B,0)),"") -> Mild spatial bias | R64: =IFERROR(INDEX(Admissions_2024_2025!R:R,MATCH($B64,Admissions_2024_2025!$B:$B,0)),"") -> 75 | S64: =IFERROR(INDEX(Admissions_2024_2025!S:S,MATCH($B64,Admissions_2024_2025!$B:$B,0)),"") -> 122 | T64: =IFERROR(INDEX(Admissions_2024_2025!T:T,MATCH($B64,Admissions_2024_2025!$B:$B,0)),"") -> 93 | U64: =IFERROR(INDEX(Admissions_2024_2025!U:U,MATCH($B64,Admissions_2024_2025!$B:$B,0)),"") -> 92 | V64: =IFERROR(INDEX(Admissions_2024_2025!V:V,MATCH($B5,Admissions_2024_2025!$B:$B,0)),"") -> 0 | W64: =IFERROR(INDEX(Admissions_2024_2025!W:W,MATCH($B64,Admissions_2024_2025!$B:$B,0)),"") -> 2023 admissions; 2019 accepted list; CAT new students
A65: Class of 2023 | B65: 30563401334 | C65: سلطان عيد سلطان المهندى | D65: =IFERROR(INDEX(Admissions_2024_2025!D:D,MATCH($B65,Admissions_2024_2025!$B:$B,0)),"") -> Umar ibn Al-Khattab Preparatory School for Boys | E65: =IFERROR(INDEX(Admissions_2024_2025!E:E,MATCH($B65,Admissions_2024_2025!$B:$B,0)),"") -> General | F65: =IFERROR(INDEX(Admissions_2024_2025!F:F,MATCH($B65,Admissions_2024_2025!$B:$B,0)),"") -> 84 | G65: =IFERROR(INDEX(Admissions_2024_2025!G:G,MATCH($B65,Admissions_2024_2025!$B:$B,0)),"") -> 0 | H65: =IFERROR(INDEX(Admissions_2024_2025!H:H,MATCH($B65,Admissions_2024_2025!$B:$B,0)),"") -> 0 | I65: =IFERROR(INDEX(Admissions_2024_2025!I:I,MATCH($B65,Admissions_2024_2025!$B:$B,0)),"") -> B1 | J65: =IFERROR(INDEX(Admissions_2024_2025!J:J,MATCH($B65,Admissions_2024_2025!$B:$B,0)),"") -> 131 | K65: =IF(J65="","",J65/250*100) -> 52.4 | L65: =IFERROR(INDEX(Admissions_2024_2025!L:L,MATCH($B65,Admissions_2024_2025!$B:$B,0)),"") -> 75 | M65: =IF(L65="","",L65/50*100) -> 150 | N65: =IF(COUNT(R65:U65)=0,"",ROUND(AVERAGE(R65:U65),0)) -> 96 | O65: =IF(N65="","",N65/142*100) -> 67.605634 | P65: =IF(COUNT(K65,M65,O65)=0,"",AVERAGE(K65,M65,O65)) -> 90.001878 | Q65: =IFERROR(INDEX(Admissions_2024_2025!Q:Q,MATCH($B65,Admissions_2024_2025!$B:$B,0)),"") -> Moderate spatial bias | R65: =IFERROR(INDEX(Admissions_2024_2025!R:R,MATCH($B65,Admissions_2024_2025!$B:$B,0)),"") -> 75 | S65: =IFERROR(INDEX(Admissions_2024_2025!S:S,MATCH($B65,Admissions_2024_2025!$B:$B,0)),"") -> 116 | T65: =IFERROR(INDEX(Admissions_2024_2025!T:T,MATCH($B65,Admissions_2024_2025!$B:$B,0)),"") -> 91 | U65: =IFERROR(INDEX(Admissions_2024_2025!U:U,MATCH($B65,Admissions_2024_2025!$B:$B,0)),"") -> 102 | V65: =IFERROR(INDEX(Admissions_2024_2025!V:V,MATCH($B6,Admissions_2024_2025!$B:$B,0)),"") -> 0 | W65: =IFERROR(INDEX(Admissions_2024_2025!W:W,MATCH($B65,Admissions_2024_2025!$B:$B,0)),"") -> 2023 admissions; 2019 accepted list; CAT new students
A66: Class of 2023 | B66: 30563404818 | C66: عبدالعزيز خالد ابراهيم الحمادى | D66: =IFERROR(INDEX(Admissions_2024_2025!D:D,MATCH($B66,Admissions_2024_2025!$B:$B,0)),"") -> Doha British School | E66: =IFERROR(INDEX(Admissions_2024_2025!E:E,MATCH($B66,Admissions_2024_2025!$B:$B,0)),"") -> British | F66: =IFERROR(INDEX(Admissions_2024_2025!F:F,MATCH($B66,Admissions_2024_2025!$B:$B,0)),"") -> Step 5 | G66: =IFERROR(INDEX(Admissions_2024_2025!G:G,MATCH($B66,Admissions_2024_2025!$B:$B,0)),"") -> 0 | H66: =IFERROR(INDEX(Admissions_2024_2025!H:H,MATCH($B66,Admissions_2024_2025!$B:$B,0)),"") -> 0 | I66: =IFERROR(INDEX(Admissions_2024_2025!I:I,MATCH($B66,Admissions_2024_2025!$B:$B,0)),"") -> B2 | J66: =IFERROR(INDEX(Admissions_2024_2025!J:J,MATCH($B66,Admissions_2024_2025!$B:$B,0)),"") -> 161 | K66: =IF(J66="","",J66/250*100) -> 64.4 | L66: =IFERROR(INDEX(Admissions_2024_2025!L:L,MATCH($B66,Admissions_2024_2025!$B:$B,0)),"") -> 78 | M66: =IF(L66="","",L66/50*100) -> 156 | N66: =IF(COUNT(R66:U66)=0,"",ROUND(AVERAGE(R66:U66),0)) -> 99 | O66: =IF(N66="","",N66/142*100) -> 69.71831 | P66: =IF(COUNT(K66,M66,O66)=0,"",AVERAGE(K66,M66,O66)) -> 96.706103 | Q66: =IFERROR(INDEX(Admissions_2024_2025!Q:Q,MATCH($B66,Admissions_2024_2025!$B:$B,0)),"") -> Mild verbal bias | R66: =IFERROR(INDEX(Admissions_2024_2025!R:R,MATCH($B66,Admissions_2024_2025!$B:$B,0)),"") -> 104 | S66: =IFERROR(INDEX(Admissions_2024_2025!S:S,MATCH($B66,Admissions_2024_2025!$B:$B,0)),"") -> 95 | T66: =IFERROR(INDEX(Admissions_2024_2025!T:T,MATCH($B66,Admissions_2024_2025!$B:$B,0)),"") -> 102 | U66: =IFERROR(INDEX(Admissions_2024_2025!U:U,MATCH($B66,Admissions_2024_2025!$B:$B,0)),"") -> 96 | V66: =IFERROR(INDEX(Admissions_2024_2025!V:V,MATCH($B7,Admissions_2024_2025!$B:$B,0)),"") -> 0 | W66: =IFERROR(INDEX(Admissions_2024_2025!W:W,MATCH($B66,Admissions_2024_2025!$B:$B,0)),"") -> 2023 admissions; 2019 accepted list; CAT new students
A67: Class of 2023 | B67: 30563400872 | C67: عبدالله جبر احمد الحجاجى | D67: =IFERROR(INDEX(Admissions_2024_2025!D:D,MATCH($B67,Admissions_2024_2025!$B:$B,0)),"") -> Khalid Bin Ahmad Preparatory School for Boys | E67: =IFERROR(INDEX(Admissions_2024_2025!E:E,MATCH($B67,Admissions_2024_2025!$B:$B,0)),"") -> General | F67: =IFERROR(INDEX(Admissions_2024_2025!F:F,MATCH($B67,Admissions_2024_2025!$B:$B,0)),"") -> 89 | G67: =IFERROR(INDEX(Admissions_2024_2025!G:G,MATCH($B67,Admissions_2024_2025!$B:$B,0)),"") -> 0 | H67: =IFERROR(INDEX(Admissions_2024_2025!H:H,MATCH($B67,Admissions_2024_2025!$B:$B,0)),"") -> 0 | I67: =IFERROR(INDEX(Admissions_2024_2025!I:I,MATCH($B67,Admissions_2024_2025!$B:$B,0)),"") -> B1 | J67: =IFERROR(INDEX(Admissions_2024_2025!J:J,MATCH($B67,Admissions_2024_2025!$B:$B,0)),"") -> 138 | K67: =IF(J67="","",J67/250*100) -> 55.2 | L67: =IFERROR(INDEX(Admissions_2024_2025!L:L,MATCH($B67,Admissions_2024_2025!$B:$B,0)),"") -> 38 | M67: =IF(L67="","",L67/50*100) -> 76 | N67: =IF(COUNT(R67:U67)=0,"",ROUND(AVERAGE(R67:U67),0)) -> 95 | O67: =IF(N67="","",N67/142*100) -> 66.901408 | P67: =IF(COUNT(K67,M67,O67)=0,"",AVERAGE(K67,M67,O67)) -> 66.033803 | Q67: =IFERROR(INDEX(Admissions_2024_2025!Q:Q,MATCH($B67,Admissions_2024_2025!$B:$B,0)),"") -> No bias | R67: =IFERROR(INDEX(Admissions_2024_2025!R:R,MATCH($B67,Admissions_2024_2025!$B:$B,0)),"") -> 77 | S67: =IFERROR(INDEX(Admissions_2024_2025!S:S,MATCH($B67,Admissions_2024_2025!$B:$B,0)),"") -> 110 | T67: =IFERROR(INDEX(Admissions_2024_2025!T:T,MATCH($B67,Admissions_2024_2025!$B:$B,0)),"") -> 105 | U67: =IFERROR(INDEX(Admissions_2024_2025!U:U,MATCH($B67,Admissions_2024_2025!$B:$B,0)),"") -> 86 | V67: =IFERROR(INDEX(Admissions_2024_2025!V:V,MATCH($B8,Admissions_2024_2025!$B:$B,0)),"") -> 0 | W67: =IFERROR(INDEX(Admissions_2024_2025!W:W,MATCH($B67,Admissions_2024_2025!$B:$B,0)),"") -> 2023 admissions; 2019 accepted list; CAT new students
A68: Class of 2023 | B68: 30563405476 | C68: عبدالله نايف ناصر النعيمى | D68: =IFERROR(INDEX(Admissions_2024_2025!D:D,MATCH($B68,Admissions_2024_2025!$B:$B,0)),"") -> Khalid ibn al-Walid Preparatory School for Boys | E68: =IFERROR(INDEX(Admissions_2024_2025!E:E,MATCH($B68,Admissions_2024_2025!$B:$B,0)),"") -> General | F68: =IFERROR(INDEX(Admissions_2024_2025!F:F,MATCH($B68,Admissions_2024_2025!$B:$B,0)),"") -> 99 | G68: =IFERROR(INDEX(Admissions_2024_2025!G:G,MATCH($B68,Admissions_2024_2025!$B:$B,0)),"") -> 0 | H68: =IFERROR(INDEX(Admissions_2024_2025!H:H,MATCH($B68,Admissions_2024_2025!$B:$B,0)),"") -> 0 | I68: =IFERROR(INDEX(Admissions_2024_2025!I:I,MATCH($B68,Admissions_2024_2025!$B:$B,0)),"") -> B2 | J68: =IFERROR(INDEX(Admissions_2024_2025!J:J,MATCH($B68,Admissions_2024_2025!$B:$B,0)),"") -> 148 | K68: =IF(J68="","",J68/250*100) -> 59.2 | L68: =IFERROR(INDEX(Admissions_2024_2025!L:L,MATCH($B68,Admissions_2024_2025!$B:$B,0)),"") -> 60 | M68: =IF(L68="","",L68/50*100) -> 120 | N68: =IF(COUNT(R68:U68)=0,"",ROUND(AVERAGE(R68:U68),0)) -> 104 | O68: =IF(N68="","",N68/142*100) -> 73.239437 | P68: =IF(COUNT(K68,M68,O68)=0,"",AVERAGE(K68,M68,O68)) -> 84.146479 | Q68: =IFERROR(INDEX(Admissions_2024_2025!Q:Q,MATCH($B68,Admissions_2024_2025!$B:$B,0)),"") -> Mild spatial bias | R68: =IFERROR(INDEX(Admissions_2024_2025!R:R,MATCH($B68,Admissions_2024_2025!$B:$B,0)),"") -> 93 | S68: =IFERROR(INDEX(Admissions_2024_2025!S:S,MATCH($B68,Admissions_2024_2025!$B:$B,0)),"") -> 111 | T68: =IFERROR(INDEX(Admissions_2024_2025!T:T,MATCH($B68,Admissions_2024_2025!$B:$B,0)),"") -> 109 | U68: =IFERROR(INDEX(Admissions_2024_2025!U:U,MATCH($B68,Admissions_2024_2025!$B:$B,0)),"") -> 104 | V68: =IFERROR(INDEX(Admissions_2024_2025!V:V,MATCH($B9,Admissions_2024_2025!$B:$B,0)),"") -> 0 | W68: =IFERROR(INDEX(Admissions_2024_2025!W:W,MATCH($B68,Admissions_2024_2025!$B:$B,0)),"") -> 2023 admissions; 2019 accepted list; CAT new students
A69: Class of 2023 | B69: 30663401667 | C69: على يوسف صالح المهندى | D69: =IFERROR(INDEX(Admissions_2024_2025!D:D,MATCH($B69,Admissions_2024_2025!$B:$B,0)),"") -> Umar ibn Al-Khattab Preparatory School for Boys | E69: =IFERROR(INDEX(Admissions_2024_2025!E:E,MATCH($B69,Admissions_2024_2025!$B:$B,0)),"") -> General | F69: =IFERROR(INDEX(Admissions_2024_2025!F:F,MATCH($B69,Admissions_2024_2025!$B:$B,0)),"") -> 91 | G69: =IFERROR(INDEX(Admissions_2024_2025!G:G,MATCH($B69,Admissions_2024_2025!$B:$B,0)),"") -> 0 | H69: =IFERROR(INDEX(Admissions_2024_2025!H:H,MATCH($B69,Admissions_2024_2025!$B:$B,0)),"") -> 0 | I69: =IFERROR(INDEX(Admissions_2024_2025!I:I,MATCH($B69,Admissions_2024_2025!$B:$B,0)),"") -> B1 | J69: =IFERROR(INDEX(Admissions_2024_2025!J:J,MATCH($B69,Admissions_2024_2025!$B:$B,0)),"") -> 131 | K69: =IF(J69="","",J69/250*100) -> 52.4 | L69: =IFERROR(INDEX(Admissions_2024_2025!L:L,MATCH($B69,Admissions_2024_2025!$B:$B,0)),"") -> 55 | M69: =IF(L69="","",L69/50*100) -> 110 | N69: =IF(COUNT(R69:U69)=0,"",ROUND(AVERAGE(R69:U69),0)) -> 93 | O69: =IF(N69="","",N69/142*100) -> 65.492958 | P69: =IF(COUNT(K69,M69,O69)=0,"",AVERAGE(K69,M69,O69)) -> 75.964319 | Q69: =IFERROR(INDEX(Admissions_2024_2025!Q:Q,MATCH($B69,Admissions_2024_2025!$B:$B,0)),"") -> Moderate spatial bias | R69: =IFERROR(INDEX(Admissions_2024_2025!R:R,MATCH($B69,Admissions_2024_2025!$B:$B,0)),"") -> 69 | S69: =IFERROR(INDEX(Admissions_2024_2025!S:S,MATCH($B69,Admissions_2024_2025!$B:$B,0)),"") -> 106 | T69: =IFERROR(INDEX(Admissions_2024_2025!T:T,MATCH($B69,Admissions_2024_2025!$B:$B,0)),"") -> 102 | U69: =IFERROR(INDEX(Admissions_2024_2025!U:U,MATCH($B69,Admissions_2024_2025!$B:$B,0)),"") -> 94 | V69: =IFERROR(INDEX(Admissions_2024_2025!V:V,MATCH($B10,Admissions_2024_2025!$B:$B,0)),"") -> 0 | W69: =IFERROR(INDEX(Admissions_2024_2025!W:W,MATCH($B69,Admissions_2024_2025!$B:$B,0)),"") -> 2023 admissions; 2019 accepted list; CAT new students
A70: Class of 2023 | B70: 30663400377 | C70: عمر سعد ابراهيم البدر | D70: =IFERROR(INDEX(Admissions_2024_2025!D:D,MATCH($B70,Admissions_2024_2025!$B:$B,0)),"") -> Doha Preparatory School for Boys | E70: =IFERROR(INDEX(Admissions_2024_2025!E:E,MATCH($B70,Admissions_2024_2025!$B:$B,0)),"") -> General | F70: =IFERROR(INDEX(Admissions_2024_2025!F:F,MATCH($B70,Admissions_2024_2025!$B:$B,0)),"") -> 100 | G70: =IFERROR(INDEX(Admissions_2024_2025!G:G,MATCH($B70,Admissions_2024_2025!$B:$B,0)),"") -> 0 | H70: =IFERROR(INDEX(Admissions_2024_2025!H:H,MATCH($B70,Admissions_2024_2025!$B:$B,0)),"") -> 0 | I70: =IFERROR(INDEX(Admissions_2024_2025!I:I,MATCH($B70,Admissions_2024_2025!$B:$B,0)),"") -> B2 | J70: =IFERROR(INDEX(Admissions_2024_2025!J:J,MATCH($B70,Admissions_2024_2025!$B:$B,0)),"") -> 167 | K70: =IF(J70="","",J70/250*100) -> 66.8 | L70: =IFERROR(INDEX(Admissions_2024_2025!L:L,MATCH($B70,Admissions_2024_2025!$B:$B,0)),"") -> 63 | M70: =IF(L70="","",L70/50*100) -> 126 | N70: =IF(COUNT(R70:U70)=0,"",ROUND(AVERAGE(R70:U70),0)) -> 101 | O70: =IF(N70="","",N70/142*100) -> 71.126761 | P70: =IF(COUNT(K70,M70,O70)=0,"",AVERAGE(K70,M70,O70)) -> 87.975587 | Q70: =IFERROR(INDEX(Admissions_2024_2025!Q:Q,MATCH($B70,Admissions_2024_2025!$B:$B,0)),"") -> No bias | R70: =IFERROR(INDEX(Admissions_2024_2025!R:R,MATCH($B70,Admissions_2024_2025!$B:$B,0)),"") -> 96 | S70: =IFERROR(INDEX(Admissions_2024_2025!S:S,MATCH($B70,Admissions_2024_2025!$B:$B,0)),"") -> 100 | T70: =IFERROR(INDEX(Admissions_2024_2025!T:T,MATCH($B70,Admissions_2024_2025!$B:$B,0)),"") -> 107 | U70: =IFERROR(INDEX(Admissions_2024_2025!U:U,MATCH($B70,Admissions_2024_2025!$B:$B,0)),"") -> 99 | V70: =IFERROR(INDEX(Admissions_2024_2025!V:V,MATCH($B11,Admissions_2024_2025!$B:$B,0)),"") -> 0 | W70: =IFERROR(INDEX(Admissions_2024_2025!W:W,MATCH($B70,Admissions_2024_2025!$B:$B,0)),"") -> 2023 admissions; 2019 accepted list; CAT new students
